Workbook

Sheet Planilha de Custo
A1: Planilha de Custos
A3: Cliente 👤: JOGOS INDÍGINAS TERRA NOVA | C3: Data 📅: | D3: 1 de maio de 2025 | E3: Nº 0100
A4: Campanha 🎯:
A5: Descritivo📝:
A6: 1) VIDEO DE ABERTURA 1m30seg
A7: 2) VIDEO GERAL DO EVENTO
A8: 3)
A9: 4)
A11: Categoria | B11: Descrição | C11: Valor Unit. (R$) | D11: Quantidade | E11: Total (R$)
A14: 1. Equipe Técnica 📦
A15: Diretor | C15: 0 | E15: =IFERROR(C15*D15,"") -> 0
A16: Diretor de Fotografia | C16: 0 | E16: =IFERROR(C16*D16,"") -> 0
A17: Operador de Câmera | C17: 0 | E17: =IFERROR(C17*D17,"") -> 0
A18: Assistente de Câmera | C18: 50 | D18: 2 | E18: =IFERROR(C18*D18,"") -> 100
A19: Gaffer (Iluminação) / elétrica | C19: 0 | E19: =IFERROR(C19*D19,"") -> 0
A20: Operador de Drone | C20: 150 | D20: 1 | E20: =IFERROR(C20*D20,"") -> 150
A21: Operador de áudio | C21: 0 | E21: =IFERROR(C21*D21,"") -> 0
A22: Cenógrafo | C22: 0 | E22: =IFERROR(C22*D22,"") -> 0
A23: Figurinista | C23: 0 | E23: =IFERROR(C23*D23,"") -> 0
A24: Maquiador(a) | C24: 0 | E24: =IFERROR(C24*D24,"") -> 0
A25: Cabelereiro | C25: 0 | E25: =IFERROR(C25*D25,"") -> 0
A26: Outros | C26: 0 | E26: =IFERROR(C26*D26,"") -> 0
A29: TOTAL | E29: =SUM(E15:E28) -> 250
A32: 2. Equipamentos 📸
A33: Câmera | C33: 0 | E33: =IFERROR(C33*D33,"") -> 0
A34: Lentes | C34: 0 | E34: =IFERROR(C34*D34,"") -> 0
A35: Iluminação | C35: 0 | E35: =IFERROR(C35*D35,"") -> 0
A36: Acessórios | C36: 0 | E36: =IFERROR(C36*D36,"") -> 0
A37: Outros | C37: 0 | E37: =IFERROR(C37*D37,"") -> 0
A38: TOTAL | E38: =SUM(E33:E37) -> 0
A40: 3. Elenco 🎭
A41: Ator | C41: 0 | E41: =IFERROR(C41*D41,"") -> 0
A42: Apresentador | C42: 0 | E42: =IFERROR(C42*D42,"") -> 0
A43: Figurante | C43: 0 | E43: =IFERROR(C43*D43,"") -> 0
A44: TOTAL | E44: =SUM(E41:E43) -> 0
A46: 4. Pós Produção 🖥️
A47: Edição de Vídeo | C47: 150 | D47: 1 | E47: =IFERROR(C47*D47,"") -> 150
A48: Color Grading | C48: 0 | E48: =IFERROR(C48*D48,"") -> 0
A49: Motion Graphics | C49: 0 | E49: =IFERROR(C49*D49,"") -> 0
A50: Editor de Audio | C50: 0 | E50: =IFERROR(C50*D50,"") -> 0
...

Sheet Orçamento Cliente
C2: sua logo aqui
B5: São Sebastião, | D5: ='Planilha de Custo'!D3 -> 1 de maio de 2025
B7: Para:
B8: Cliente / Campanha:
B9: A/C:
B11: Segue abaixo orçamento para produção de:
C13: ='Planilha de Custo'!A6 -> 1) VIDEO DE ABERTURA 1m30seg
C14: ='Planilha de Custo'!A7 -> 2) VIDEO GERAL DO EVENTO
C15: ='Planilha de Custo'!A8 -> 3)
C16: ='Planilha de Custo'!A9 -> 4)
B18: Neste orçamento estamos considerado os seguintes itens:
C20: ='Planilha de Custo'!$A$14 -> 1. Equipe Técnica 📦 | F20: ='Planilha de Custo'!$A$40 -> 3. Elenco 🎭
C21: ='Planilha de Custo'!A15 -> Diretor | F21: ='Planilha de Custo'!A$41 -> Ator
C22: ='Planilha de Custo'!A16 -> Diretor de Fotografia | F22: ='Planilha de Custo'!A42 -> Apresentador
C23: ='Planilha de Custo'!A17 -> Operador de Câmera | F23: ='Planilha de Custo'!A43 -> Figurante
C24: ='Planilha de Custo'!A18 -> Assistente de Câmera | F24: ='Planilha de Custo'!$A$46 -> 4. Pós Produção 🖥️
C25: ='Planilha de Custo'!A19 -> Gaffer (Iluminação) / elétrica | F25: ='Planilha de Custo'!A47 -> Edição de Vídeo
C26: ='Planilha de Custo'!A20 -> Operador de Drone | F26: ='Planilha de Custo'!A48 -> Color Grading
C27: ='Planilha de Custo'!A21 -> Operador de áudio | F27: ='Planilha de Custo'!A49 -> Motion Graphics
C28: ='Planilha de Custo'!A22 -> Cenógrafo | F28: ='Planilha de Custo'!A50 -> Editor de Audio
C29: ='Planilha de Custo'!A23 -> Figurinista | F29: ='Planilha de Custo'!A51 -> Trilha Sonora
C30: ='Planilha de Custo'!A24 -> Maquiador(a) | F30: ='Planilha de Custo'!A52 -> Locução
C31: ='Planilha de Custo'!A25 -> Cabelereiro | F31: ='Planilha de Custo'!$A$56 -> 5.Logistica 🚚
C32: ='Planilha de Custo'!$A$32 -> 2. Equipamentos 📸 | F32: ='Planilha de Custo'!A57 -> Transporte
C33: ='Planilha de Custo'!A33 -> Câmera | F33: ='Planilha de Custo'!A58 -> Alimentação
C34: ='Planilha de Custo'!A34 -> Lentes | F34: ='Planilha de Custo'!A59 -> Hospedagem
C35: ='Planilha de Custo'!A35 -> Iluminação | F35: ='Planilha de Custo'!A60 -> Locacão
C36: ='Planilha de Custo'!A36 -> Acessórios
C40: Total Bruto: | D40: ='Planilha de Custo'!E78 -> 1210
C41: Condições de pagamento: Entrada 40% + 28ddl
C43: OBSERVAÇOES:
C44: - Orçamento válido por cinco (5) dias após data de envio.
C45: - Serão realizadas 2 rodadas de alteração. Acima disso, será cobrado adicional.
C46: - Arquivos finais serão entregues por link de download. Armazenamento garantido por 30 dias.
C47: - As imagens brutas (sem tratamento ou edição) não são liberadas.
C48: • As imagens finalizadas têm uso restrito à campanha acordada.
C49: -Em caso de cancelamento após início do projeto, poderá haver cobrança proporcional aos custos já ocorridos.
G57: Nome / Cargo / Assinatura
